Workbook

Sheet A-Z player stats
A1: Player | B1: Nation | C1: Pos | D1: Squad | E1: Age | F1: Born | G1: MP | H1: Starts | I1: Min | J1: 90s | K1: Gls | L1: Ast | M1: G+A | N1: G-PK | O1: PK | P1: PKatt | Q1: CrdY | R1: CrdR | S1: Gls/G | T1: Ast/G | U1: G+A/G | V1: G-PK/G | W1: G+A-PK/G | X1: Matches
A2: Aaron Bolger | B2: IRL | C2: MF | D2: St Patrick's | E2: 23 | F2: 2000 | G2: 17 | H2: 10 | I2: 960 | J2: 10.7 | K2: 0 | L2: 0 | M2: 0 | N2: 0 | O2: 0 | P2: 0 | Q2: 3 | R2: 0 | S2: 0 | T2: 0 | U2: 0 | V2: 0 | W2: 0 | X2: Matches
A3: Aaron Greene | B3: IRL | C3: FW,MF | D3: Shamrock Rovers | E3: 34 | F3: 1990 | G3: 30 | H3: 16 | I3: 1687 | J3: 18.7 | K3: 8 | L3: 2 | M3: 10 | N3: 8 | O3: 0 | P3: 0 | Q3: 2 | R3: 0 | S3: 0.43 | T3: 0.11 | U3: 0.53 | V3: 0.43 | W3: 0.53 | X3: Matches
A4: Aaron Haper-Bailey | B4: ENG | C4: DF | D4: Drogheda United | E4: 22 | F4: 2001 | G4: 3 | H4: 1 | I4: 153 | J4: 1.7 | K4: 0 | L4: 0 | M4: 0 | N4: 0 | O4: 0 | P4: 0 | Q4: 0 | R4: 0 | S4: 0 | T4: 0 | U4: 0 | V4: 0 | W4: 0 | X4: Matches
A5: Aaron McEneff | B5: IRL | C5: MF | D5: Shamrock Rovers | E5: 28 | F5: 1995 | G5: 12 | H5: 2 | I5: 403 | J5: 4.5 | K5: 0 | L5: 0 | M5: 0 | N5: 0 | O5: 0 | P5: 0 | Q5: 1 | R5: 0 | S5: 0 | T5: 0 | U5: 0 | V5: 0 | W5: 0 | X5: Matches
A6: Aaron McNally | B6: IRL | C6: MF | D6: Drogheda United | E6: 23 | F6: 2000 | G6: 12 | H6: 4 | I6: 486 | J6: 5.4 | K6: 1 | L6: 0 | M6: 1 | N6: 1 | O6: 0 | P6: 0 | Q6: 1 | R6: 0 | S6: 0.19 | T6: 0 | U6: 0.19 | V6: 0.19 | W6: 0.19 | X6: Matches
A7: Aboubacar Keita | B7: USA | C7: DF | D7: Bohemian FC | E7: 23 | F7: 2000 | G7: 16 | H7: 12 | I7: 1121 | J7: 12.5 | K7: 1 | L7: 0 | M7: 1 | N7: 1 | O7: 0 | P7: 0 | Q7: 4 | R7: 0 | S7: 0.08 | T7: 0 | U7: 0.08 | V7: 0.08 | W7: 0.08 | X7: Matches
A8: Adam Foley | B8: IRL | C8: MF,FW | D8: Drogheda United | E8: 34 | F8: 1989 | G8: 33 | H8: 20 | I8: 1770 | J8: 19.7 | K8: 4 | L8: 3 | M8: 7 | N8: 4 | O8: 0 | P8: 0 | Q8: 6 | R8: 0 | S8: 0.2 | T8: 0.15 | U8: 0.36 | V8: 0.2 | W8: 0.36 | X8: Matches
A9: Adam McDonnell | B9: IRL | C9: MF | D9: Bohemian FC | E9: 26 | F9: 1997 | G9: 35 | H9: 33 | I9: 2655 | J9: 29.5 | K9: 0 | L9: 2 | M9: 2 | N9: 0 | O9: 0 | P9: 0 | Q9: 8 | R9: 0 | S9: 0 | T9: 0.07 | U9: 0.07 | V9: 0 | W9: 0.07 | X9: Matches
A10: Adam O'Reilly | B10: IRL | C10: MF | D10: Derry City | E10: 22 | F10: 2001 | G10: 35 | H10: 32 | I10: 2842 | J10: 31.6 | K10: 1 | L10: 0 | M10: 1 | N10: 1 | O10: 0 | P10: 0 | Q10: 9 | R10: 0 | S10: 0.03 | T10: 0 | U10: 0.03 | V10: 0.03 | W10: 0.03 | X10: Matches
A11: Aidan Keena | B11: IRL | C11: FW | D11: St Patrick's | E11: 24 | F11: 1999 | G11: 11 | H11: 9 | I11: 702 | J11: 7.8 | K11: 5 | L11: 0 | M11: 5 | N11: 4 | O11: 1 | P11: 1 | Q11: 0 | R11: 0 | S11: 0.64 | T11: 0 | U11: 0.64 | V11: 0.51 | W11: 0.51 | X11: Matches
A12: Aiden O'Brien | B12: IRL | C12: FW | D12: Shelbourne FC | E12: 30 | F12: 1993 | G12: 8 | H12: 5 | I12: 459 | J12: 5.1 | K12: 1 | L12: 0 | M12: 1 | N12: 1 | O12: 0 | P12: 0 | Q12: 0 | R12: 0 | S12: 0.2 | T12: 0 | U12: 0.2 | V12: 0.2 | W12: 0.2 | X12: Matches
A13: Al Amin Kazeem | B13: ENG | C13: DF | D13: St Patrick's | E13: 21 | F13: 2002 | G13: 8 | H13: 2 | I13: 210 | J13: 2.3 | K13: 1 | L13: 0 | M13: 1 | N13: 1 | O13: 0 | P13: 0 | Q13: 1 | R13: 0 | S13: 0.43 | T13: 0 | U13: 0.43 | V13: 0.43 | W13: 0.43 | X13: Matches
... A96: Ellis Chapman | B96: ENG | C96: MF | D96: Sligo Rovers | E96: 23 | F96: 2001 | G96: 34 | H96: 33 | I96: 2764 | J96: 30.7 | K96: 9 | L96: 4 | M96: 13 | N96: 7 | O96: 2 | P96: 2 | Q96: 7 | R96: 0 | S96: 0.29 | T96: 0.13 | U96: 0.42 | V96: 0.23 | W96: 0.36 | X96: Matches
A97: Emre Topcu | C97: MF | D97: Drogheda United | E97: 18 | F97: 2005 | G97: 1 | H97: 0 | I97: 15 | J97: 0.2 | K97: 0 | L97: 0 | M97: 0 | N97: 0 | O97: 0 | P97: 0 | Q97: 0 | R97: 0 | S97: 0 | T97: 0 | U97: 0 | V97: 0 | W97: 0 | X97: Matches
A98: Eoin Kenny | B98: NIR | C98: FW | D98: Dundalk FC | E98: 18 | F98: 2005 | G98: 25 | H98: 9 | I98: 864 | J98: 9.6 | K98: 2 | L98: 1 | M98: 3 | N98: 2 | O98: 0 | P98: 0 | Q98: 5 | R98: 0 | S98: 0.21 | T98: 0.1 | U98: 0.31 | V98: 0.21 | W98: 0.31 | X98: Matches
A99: Evan Caffrey | B99: IRL | C99: MF | D99: Shelbourne FC | E99: 20 | F99: 2003 | G99: 34 | H99: 17 | I99: 1822 | J99: 20.2 | K99: 3 | L99: 2 | M99: 5 | N99: 3 | O99: 0 | P99: 0 | Q99: 4 | R99: 0 | S99: 0.15 | T99: 0.1 | U99: 0.25 | V99: 0.15 | W99: 0.25 | X99: Matches
A100: Evan Haddock | B100: IRL | C100: MF | D100: Drogheda United | E100: 18 | F100: 2005 | G100: 1 | H100: 0 | I100: 5 | J100: 0.1 | K100: 0 | L100: 0 | M100: 0 | N100: 0 | O100: 0 | P100: 0 | Q100: 0 | R100: 0 | S100: 0 | T100: 0 | U100: 0 | V100: 0 | W100: 0 | X100: Matches
A101: Evan Weir | B101: IRL | C101: DF,MF | D101: Drogheda United | E101: 21 | F101: 2002 | G101: 19 | H101: 19 | I101: 1637 | J101: 18.2 | K101: 4 | L101: 2 | M101: 6 | N101: 4 | O101: 0 | P101: 0 | Q101: 5 | R101: 0 | S101: 0.22 | T101: 0.11 | U101: 0.33 | V101: 0.22 | W101: 0.33 | X101: Matches
A102: Fabrice Hartmann | B102: GER | C102: MF,FW | D102: Sligo Rovers | E102: 22 | F102: 2001 | G102: 21 | H102: 19 | I102: 1390 | J102: 15.4 | K102: 4 | L102: 3 | M102: 7 | N102: 4 | O102: 0 | P102: 0 | Q102: 4 | R102: 0 | S102: 0.26 | T102: 0.19 | U102: 0.45 | V102: 0.26 | W102: 0.45 | X102: Matches
A103: Felix Goddard | B103: ENG | C103: GK | D103: Dundalk FC | E103: 19 | F103: 2004 | G103: 6 | H103: 6 | I103: 540 | J103: 6 | K103: 0 | L103: 0 | M103: 0 | N103: 0 | O103: 0 | P103: 0 | Q103: 0 | R103: 0 | S103: 0 | T103: 0 | U103: 0 | V103: 0 | W103: 0 | X103: Matches
A104: Filip Piszczek | B104: POL | C104: FW | D104: Bohemian FC | E104: 28 | F104: 1995 | G104: 21 | H104: 4 | I104: 692 | J104: 7.7 | K104: 2 | L104: 1 | M104: 3 | N104: 2 | O104: 0 | P104: 0 | Q104: 9 | R104: 0 | S104: 0.26 | T104: 0.13 | U104: 0.39 | V104: 0.26 | W104: 0.39 | X104: Matches
A105: Francely Lomboto | B105: IRL | C105: FW | D105: Galway United | E105: 23 | F105: 2000 | G105: 20 | H105: 2 | I105: 417 | J105: 4.6 | K105: 1 | L105: 0 | M105: 1 | N105: 1 | O105: 0 | P105: 1 | Q105: 1 | R105: 0 | S105: 0.22 | T105: 0 | U105: 0.22 | V105: 0.22 | W105: 0.22 | X105: Matches
A106: Frantz Pierrot | B106: HAI | C106: FW | D106: Drogheda United | E106: 24 | F106: 1999 | G106: 31 | H106: 24 | I106: 2064 | J106: 22.9 | K106: 10 | L106: 1 | M106: 11 | N106: 9 | O106: 1 | P106: 1 | Q106: 6 | R106: 1 | S106: 0.44 | T106: 0.04 | U106: 0.48 | V106: 0.39 | W106: 0.44 | X106: Matches
A107: Gareth McElroy | B107: IRL | C107: DF | D107: Sligo Rovers | E107: 16 | F107: 2007 | G107: 4 | H107: 4 | I107: 358 | J107: 4 | K107: 0 | L107: 0 | M107: 0 | N107: 0 | O107: 0 | P107: 0 | Q107: 2 | R107: 0 | S107: 0 | T107: 0 | U107: 0 | V107: 0 | W107: 0 | X107: Matches
A108: Garry Buckley | B108: IRL | C108: DF,MF | D108: Galway United | E108: 30 | F108: 1993 | G108: 21 | H108: 18 | I108: 1649 | J108: 18.3 | K108: 0 | L108: 0 | M108: 0 | N108: 0 | O108: 0 | P108: 0 | Q108: 4 | R108: 0 | S108: 0 | T108: 0 | U108: 0 | V108: 0 | W108: 0 | X108: Matches
A109: Gary Deegan | B109: IRL | C109: MF | D109: Drogheda United | E109: 36 | F109: 1987 | G109: 22 | H109: 18 | I109: 1669 | J109: 18.5 | K109: 0 | L109: 1 | M109: 1 | N109: 0 | O109: 0 | P109: 0 | Q109: 6 | R109: 0 | S109: 0 | T109: 0.05 | U109: 0.05 | V109: 0 | W109: 0.05 | X109: Matches
... A132: James Bolger | B132: IRL | C132: DF | D132: Drogheda United | E132: 23 | F132: 2000 | G132: 12 | H132: 12 | I132: 1031 | J132: 11.5 | K132: 0 | L132: 0 | M132: 0 | N132: 0 | O132: 0 | P132: 0 | Q132: 3 | R132: 0 | S132: 0 | T132: 0 | U132: 0 | V132: 0 | W132: 0 | X132: Matches
A133: James Byrne | B133: #VALUE! | C133: MF | D133: Drogheda United | G133: 1 | H133: 0 | I133: 20 | J133: 0.2 | K133: 0 | L133: 0 | M133: 0 | N133: 0 | O133: 0 | P133: 0 | Q133: 0 | R133: 0 | S133: 0 | T133: 0 | U133: 0 | V133: 0 | W133: 0 | X133: Matches
A134: James Clarke | B134: IRL | C134: MF,FW | D134: Bohemian FC | E134: 23 | F134: 2001 | G134: 34 | H134: 26 | I134: 2295 | J134: 25.5 | K134: 4 | L134: 1 | M134: 5 | N134: 4 | O134: 0 | P134: 0 | Q134: 7 | R134: 0 | S134: 0.16 | T134: 0.04 | U134: 0.2 | V134: 0.16 | W134: 0.2 | X134: Matches
A135: James Gullan | B135: SCO | C135: FW | D135: Dundalk FC | E135: 24 | F135: 1999 | G135: 31 | H135: 24 | I135: 2079 | J135: 23.1 | K135: 6 | L135: 1 | M135: 7 | N135: 5 | O135: 1 | P135: 1 | Q135: 5 | R135: 0 | S135: 0.26 | T135: 0.04 | U135: 0.3 | V135: 0.22 | W135: 0.26 | X135: Matches
A136: James McManus | B136: IRL | C136: MF | D136: Bohemian FC | E136: 18 | F136: 2005 | G136: 11 | H136: 8 | I136: 682 | J136: 7.6 | K136: 0 | L136: 0 | M136: 0 | N136: 0 | O136: 0 | P136: 0 | Q136: 2 | R136: 0 | S136: 0 | T136: 0 | U136: 0 | V136: 0 | W136: 0 | X136: Matches
A137: James Talbot | B137: IRL | C137: GK | D137: Bohemian FC | E137: 26 | F137: 1997 | G137: 2 | H137: 2 | I137: 180 | J137: 2 | K137: 0 | L137: 0 | M137: 0 | N137: 0 | O137: 0 | P137: 0 | Q137: 0 | R137: 0 | S137: 0 | T137: 0 | U137: 0 | V137: 0 | W137: 0 | X137: Matches
A138: Jamie Lennon | B138: IRL | C138: MF | D138: St Patrick's | E138: 25 | F138: 1998 | G138: 34 | H138: 33 | I138: 2940 | J138: 32.7 | K138: 2 | L138: 1 | M138: 3 | N138: 2 | O138: 0 | P138: 0 | Q138: 12 | R138: 0 | S138: 0.06 | T138: 0.03 | U138: 0.09 | V138: 0.06 | W138: 0.09 | X138: Matches
A139: Jamie Walker | B139: SCO | C139: DF | D139: Dundalk FC | E139: 22 | F139: 2001 | G139: 3 | H139: 3 | I139: 216 | J139: 2.4 | K139: 0 | L139: 0 | M139: 0 | N139: 0 | O139: 0 | P139: 0 | Q139: 0 | R139: 0 | S139: 0 | T139: 0 | U139: 0 | V139: 0 | W139: 0 | X139: Matches
A140: Jason McClelland | B140: IRL | C140: MF,FW | D140: St Patrick's | E140: 26 | F140: 1997 | G140: 21 | H140: 5 | I140: 624 | J140: 6.9 | K140: 1 | L140: 1 | M140: 2 | N140: 1 | O140: 0 | P140: 0 | Q140: 0 | R140: 0 | S140: 0.14 | T140: 0.14 | U140: 0.29 | V140: 0.14 | W140: 0.29 | X140: Matches
A141: Jeannot Esua | B141: CMR | C141: DF | D141: Galway United | E141: 27 | F141: 1996 | G141: 27 | H141: 23 | I141: 2093 | J141: 23.3 | K141: 0 | L141: 0 | M141: 0 | N141: 0 | O141: 0 | P141: 0 | Q141: 2 | R141: 0 | S141: 0 | T141: 0 | U141: 0 | V141: 0 | W141: 0 | X141: Matches
A142: Jethren Barr | B142: RSA | C142: GK | D142: Drogheda United | E142: 28 | F142: 1995 | G142: 7 | H142: 7 | I142: 613 | J142: 6.8 | K142: 0 | L142: 0 | M142: 0 | N142: 0 | O142: 0 | P142: 0 | Q142: 0 | R142: 1 | S142: 0 | T142: 0 | U142: 0 | V142: 0 | W142: 0 | X142: Matches
A143: Jevon Mills | B143: IRL | C143: DF | D143: Bohemian FC | E143: 20 | F143: 2003 | G143: 24 | H143: 18 | I143: 1669 | J143: 18.5 | K143: 1 | L143: 0 | M143: 1 | N143: 1 | O143: 0 | P143: 0 | Q143: 4 | R143: 0 | S143: 0.05 | T143: 0 | U143: 0.05 | V143: 0.05 | W143: 0.05 | X143: Matches
A144: Jimmy Keohane | B144: IRL | C144: MF | D144: Galway United | E144: 33 | F144: 1991 | G144: 15 | H144: 15 | I144: 1342 | J144: 14.9 | K144: 2 | L144: 0 | M144: 2 | N144: 2 | O144: 0 | P144: 0 | Q144: 0 | R144: 0 | S144: 0.13 | T144: 0 | U144: 0.13 | V144: 0.13 | W144: 0.13 | X144: Matches
...

Sheet Completed Table
G1: Playing Time | K1: Performance | Q1: CrdY | R1: CrdR | S1: Per 90 Minutes | X1: Height | Y1: Value | Z1: Average goals conceeded
A2: Player | B2: Nation | C2: Pos | D2: Squad | E2: Age | F2: Born | G2: MP | H2: Starts | I2: Min | J2: 90s | K2: Gls | L2: Ast | M2: G+A | N2: G-PK | O2: PK | P2: PKatt | Q2: CrdY | R2: CrdR | S2: Gls_90 | T2: Ast | U2: G+A | V2: G-PK | W2: G+A-PK | X2: Height | Y2: Value | Z2: Average goals conceeded | AA2: Positon (Truncated) | AB2: Weighted defensive score | AC2: defence metric | AF2: =IF(RIGHT(Y2,1)="k", VALUE(SUBSTITUTE(SUBSTITUTE(Y2,"€",""),"k",""))*1000, IF(RIGHT(Y2,1)="m", VALUE(SUBSTITUTE(SUBSTITUTE(Y2,"€",""),"m",""))*1000000, VALUE(SUBSTITUTE(Y2,"€","")))) -> #VALUE!
A3: Aaron Bolger | B3: IRL | C3: MF | D3: St Patrick's | E3: 23 | F3: 2000 | G3: 17 | H3: 10 | I3: 960 | J3: 10.7 | K3: 0 | L3: 0 | M3: 0 | N3: 0 | O3: 0 | P3: 0 | Q3: 3 | R3: 0 | S3: 0 | T3: 0 | U3: 0 | V3: 0 | W3: 0 | Y3: €91k | Z3: 1.0277778 | AA3: =IF(OR(ISNUMBER(SEARCH("DF", C3)), ISNUMBER(SEARCH("GK", C3))), "D", IF(ISNUMBER(SEARCH("MF", C3)), "M", IF(ISNUMBER(SEARCH("FW", C3)), "A","Unknown"))) -> M | AB3: =Z3 * IF(AA3="M", 2, IF(AA3="A", 4, 1)) -> 2.0555556 | AC3: =1/(AB3) -> 0.48648649 | AD3: Defender goals scored | AE3: =AVERAGEIF($AA$2:$AA$100, "D", $S$2:$S$100) -> 0.035526316 | AF3: =IF(RIGHT(Y3,1)="k", VALUE(SUBSTITUTE(SUBSTITUTE(Y3,"€",""),"k",""))*1000, IF(RIGHT(Y3,1)="m", VALUE(SUBSTITUTE(SUBSTITUTE(Y3,"€",""),"m",""))*1000000, VALUE(SUBSTITUTE(Y3,"€","")))) -> 91000
A4: Aaron Greene | B4: IRL | C4: FW,MF | D4: Shamrock Rovers | E4: 34 | F4: 1990 | G4: 30 | H4: 16 | I4: 1687 | J4: 18.7 | K4: 8 | L4: 2 | M4: 10 | N4: 8 | O4: 0 | P4: 0 | Q4: 2 | R4: 0 | S4: 0.43 | T4: 0.11 | U4: 0.53 | V4: 0.43 | W4: 0.53 | X4: 1,70m | Y4: €100k | Z4: 0.97222222 | AA4: =IF(OR(ISNUMBER(SEARCH("DF", C4)), ISNUMBER(SEARCH("GK", C4))), "D", IF(ISNUMBER(SEARCH("MF", C4)), "M", IF(ISNUMBER(SEARCH("FW", C4)), "A","Unknown"))) -> M | AB4: =Z4 * IF(AA4="M", 2, IF(AA4="A", 4, 1)) -> 1.9444444 | AC4: =1/(AB4) -> 0.51428571 | AD4: Defender Goals concieded | AE4: =AVERAGEIF($AA$2:$AA$100, "D", $AC$2:$AC$100) -> 0.92231648 | AF4: =IF(RIGHT(Y4,1)="k", VALUE(SUBSTITUTE(SUBSTITUTE(Y4,"€",""),"k",""))*1000, IF(RIGHT(Y4,1)="m", VALUE(SUBSTITUTE(SUBSTITUTE(Y4,"€",""),"m",""))*1000000, VALUE(SUBSTITUTE(Y4,"€","")))) -> 100000
A5: Aaron Haper-Bailey | B5: ENG | C5: DF | D5: Drogheda United | E5: 22 | F5: 2001 | G5: 3 | H5: 1 | I5: 153 | J5: 1.7 | K5: 0 | L5: 0 | M5: 0 | N5: 0 | O5: 0 | P5: 0 | Q5: 0 | R5: 0 | S5: 0 | T5: 0 | U5: 0 | V5: 0 | W5: 0 | X5: 1,81m | Y5: €50k | Z5: 1.6111111 | AA5: =IF(OR(ISNUMBER(SEARCH("DF", C5)), ISNUMBER(SEARCH("GK", C5))), "D", IF(ISNUMBER(SEARCH("MF", C5)), "M", IF(ISNUMBER(SEARCH("FW", C5)), "A","Unknown"))) -> D | AB5: =Z5 * IF(AA5="M", 2, IF(AA5="A", 4, 1)) -> 1.6111111 | AC5: =1/(AB5) -> 0.62068966 | AD5: Attacker goals scored | AE5: =AVERAGEIF($AA$2:$AA$100, "A", $S$2:$S$100) -> 0.42727273 | AF5: =IF(RIGHT(Y5,1)="k", VALUE(SUBSTITUTE(SUBSTITUTE(Y5,"€",""),"k",""))*1000, IF(RIGHT(Y5,1)="m", VALUE(SUBSTITUTE(SUBSTITUTE(Y5,"€",""),"m",""))*1000000, VALUE(SUBSTITUTE(Y5,"€","")))) -> 50000
A6: Aaron McEneff | B6: IRL | C6: MF | D6: Shamrock Rovers | E6: 28 | F6: 1995 | G6: 12 | H6: 2 | I6: 403 | J6: 4.5 | K6: 0 | L6: 0 | M6: 0 | N6: 0 | O6: 0 | P6: 0 | Q6: 1 | R6: 0 | S6: 0 | T6: 0 | U6: 0 | V6: 0 | W6: 0 | X6: 1,75m | Y6: €400k | Z6: 0.97222222 | AA6: =IF(OR(ISNUMBER(SEARCH("DF", C6)), ISNUMBER(SEARCH("GK", C6))), "D", IF(ISNUMBER(SEARCH("MF", C6)), "M", IF(ISNUMBER(SEARCH("FW", C6)), "A","Unknown"))) -> M | AB6: =Z6 * IF(AA6="M", 2, IF(AA6="A", 4, 1)) -> 1.9444444 | AC6: =1/(AB6) -> 0.51428571 | AD6: Attaxker goals concieded | AE6: =AVERAGEIF($AA$2:$AA$100, "A", $AC$2:$AC$100) -> 0.24641914 | AF6: =IF(RIGHT(Y6,1)="k", VALUE(SUBSTITUTE(SUBSTITUTE(Y6,"€",""),"k",""))*1000, IF(RIGHT(Y6,1)="m", VALUE(SUBSTITUTE(SUBSTITUTE(Y6,"€",""),"m",""))*1000000, VALUE(SUBSTITUTE(Y6,"€","")))) -> 400000
A7: Aaron McNally | B7: IRL | C7: MF | D7: Drogheda United | E7: 23 | F7: 2000 | G7: 12 | H7: 4 | I7: 486 | J7: 5.4 | K7: 1 | L7: 0 | M7: 1 | N7: 1 | O7: 0 | P7: 0 | Q7: 1 | R7: 0 | S7: 0.19 | T7: 0 | U7: 0.19 | V7: 0.19 | W7: 0.19 | X7: 1,73m | Y7: €19k | Z7: 1.6111111 | AA7: =IF(OR(ISNUMBER(SEARCH("DF", C7)), ISNUMBER(SEARCH("GK", C7))), "D", IF(ISNUMBER(SEARCH("MF", C7)), "M", IF(ISNUMBER(SEARCH("FW", C7)), "A","Unknown"))) -> M | AB7: =Z7 * IF(AA7="M", 2, IF(AA7="A", 4, 1)) -> 3.2222222 | AC7: =1/(AB7) -> 0.31034483 | AF7: =IF(RIGHT(Y7,1)="k", VALUE(SUBSTITUTE(SUBSTITUTE(Y7,"€",""),"k",""))*1000, IF(RIGHT(Y7,1)="m", VALUE(SUBSTITUTE(SUBSTITUTE(Y7,"€",""),"m",""))*1000000, VALUE(SUBSTITUTE(Y7,"€","")))) -> 19000
A8: Aboubacar Keita | B8: USA | C8: DF | D8: Bohemian FC | E8: 23 | F8: 2000 | G8: 16 | H8: 12 | I8: 1121 | J8: 12.5 | K8: 1 | L8: 0 | M8: 1 | N8: 1 | O8: 0 | P8: 0 | Q8: 4 | R8: 0 | S8: 0.08 | T8: 0 | U8: 0.08 | V8: 0.08 | W8: 0.08 | X8: 1,88m | Y8: €1.00m | Z8: 1.1944444 | AA8: =IF(OR(ISNUMBER(SEARCH("DF", C8)), ISNUMBER(SEARCH("GK", C8))), "D", IF(ISNUMBER(SEARCH("MF", C8)), "M", IF(ISNUMBER(SEARCH("FW", C8)), "A","Unknown"))) -> D | AB8: =Z8 * IF(AA8="M", 2, IF(AA8="A", 4, 1)) -> 1.1944444 | AC8: =1/(AB8) -> 0.8372093 | AD8: Av defender cost | AE8: =AVERAGEIF($AA$2:$AA$100,"D",$AF$2:$AF$100) -> 124157.89 | AF8: =IF(RIGHT(Y8,1)="k", VALUE(SUBSTITUTE(SUBSTITUTE(Y8,"€",""),"k",""))*1000, IF(RIGHT(Y8,1)="m", VALUE(SUBSTITUTE(SUBSTITUTE(Y8,"€",""),"m",""))*1000000, VALUE(SUBSTITUTE(Y8,"€","")))) -> 1000000
A9: Adam Foley | B9: IRL | C9: MF,FW | D9: Drogheda United | E9: 34 | F9: 1989 | G9: 33 | H9: 20 | I9: 1770 | J9: 19.7 | K9: 4 | L9: 3 | M9: 7 | N9: 4 | O9: 0 | P9: 0 | Q9: 6 | R9: 0 | S9: 0.2 | T9: 0.15 | U9: 0.36 | V9: 0.2 | W9: 0.36 | X9: 1,88m | Y9: €50k | Z9: 1.6111111 | AA9: =IF(OR(ISNUMBER(SEARCH("DF", C9)), ISNUMBER(SEARCH("GK", C9))), "D", IF(ISNUMBER(SEARCH("MF", C9)), "M", IF(ISNUMBER(SEARCH("FW", C9)), "A","Unknown"))) -> M | AB9: =Z9 * IF(AA9="M", 2, IF(AA9="A", 4, 1)) -> 3.2222222 | AC9: =1/(AB9) -> 0.31034483 | AD9: av attyacker cost | AE9: =AVERAGEIF($AA$2:$AA$100,"A",$AF$2:$AF$100) -> 141636.36 | AF9: =IF(RIGHT(Y9,1)="k", VALUE(SUBSTITUTE(SUBSTITUTE(Y9,"€",""),"k",""))*1000, IF(RIGHT(Y9,1)="m", VALUE(SUBSTITUTE(SUBSTITUTE(Y9,"€",""),"m",""))*1000000, VALUE(SUBSTITUTE(Y9,"€","")))) -> 50000
A10: Adam McDonnell | B10: IRL | C10: MF | D10: Bohemian FC | E10: 26 | F10: 1997 | G10: 35 | H10: 33 | I10: 2655 | J10: 29.5 | K10: 0 | L10: 2 | M10: 2 | N10: 0 | O10: 0 | P10: 0 | Q10: 8 | R10: 0 | S10: 0 | T10: 0.07 | U10: 0.07 | V10: 0 | W10: 0.07 | X10: 1,74m | Y10: €100k | Z10: 1.1944444 | AA10: =IF(OR(ISNUMBER(SEARCH("DF", C10)), ISNUMBER(SEARCH("GK", C10))), "D", IF(ISNUMBER(SEARCH("MF", C10)), "M", IF(ISNUMBER(SEARCH("FW", C10)), "A","Unknown"))) -> M | AB10: =Z10 * IF(AA10="M", 2, IF(AA10="A", 4, 1)) -> 2.3888889 | AC10: =1/(AB10) -> 0.41860465 | AF10: =IF(RIGHT(Y10,1)="k", VALUE(SUBSTITUTE(SUBSTITUTE(Y10,"€",""),"k",""))*1000, IF(RIGHT(Y10,1)="m", VALUE(SUBSTITUTE(SUBSTITUTE(Y10,"€",""),"m",""))*1000000, VALUE(SUBSTITUTE(Y10,"€","")))) -> 100000
A11: Adam O'Reilly | B11: IRL | C11: MF | D11: Derry City | E11: 22 | F11: 2001 | G11: 35 | H11: 32 | I11: 2842 | J11: 31.6 | K11: 1 | L11: 0 | M11: 1 | N11: 1 | O11: 0 | P11: 0 | Q11: 9 | R11: 0 | S11: 0.03 | T11: 0 | U11: 0.03 | V11: 0.03 | W11: 0.03 | X11: 1,68m | Y11: €400k | Z11: 0.86111111 | AA11: =IF(OR(ISNUMBER(SEARCH("DF", C11)), ISNUMBER(SEARCH("GK", C11))), "D", IF(ISNUMBER(SEARCH("MF", C11)), "M", IF(ISNUMBER(SEARCH("FW", C11)), "A","Unknown"))) -> M | AB11: =Z11 * IF(AA11="M", 2, IF(AA11="A", 4, 1)) -> 1.7222222 | AC11: =1/(AB11) -> 0.58064516 | AF11: =IF(RIGHT(Y11,1)="k", VALUE(SUBSTITUTE(SUBSTITUTE(Y11,"€",""),"k",""))*1000, IF(RIGHT(Y11,1)="m", VALUE(SUBSTITUTE(SUBSTITUTE(Y11,"€",""),"m",""))*1000000, VALUE(SUBSTITUTE(Y11,"€","")))) -> 400000
A12: Aidan Keena | B12: IRL | C12: FW | D12: St Patrick's | E12: 24 | F12: 1999 | G12: 11 | H12: 9 | I12: 702 | J12: 7.8 | K12: 5 | L12: 0 | M12: 5 | N12: 4 | O12: 1 | P12: 1 | Q12: 0 | R12: 0 | S12: 0.64 | T12: 0 | U12: 0.64 | V12: 0.51 | W12: 0.51 | X12: 1,81m | Y12: €200k | Z12: 1.0277778 | AA12: =IF(OR(ISNUMBER(SEARCH("DF", C12)), ISNUMBER(SEARCH("GK", C12))), "D", IF(ISNUMBER(SEARCH("MF", C12)), "M", IF(ISNUMBER(SEARCH("FW", C12)), "A","Unknown"))) -> A | AB12: =Z12 * IF(AA12="M", 2, IF(AA12="A", 4, 1)) -> 4.1111111 | AC12: =1/(AB12) -> 0.24324324 | AF12: =IF(RIGHT(Y12,1)="k", VALUE(SUBSTITUTE(SUBSTITUTE(Y12,"€",""),"k",""))*1000, IF(RIGHT(Y12,1)="m", VALUE(SUBSTITUTE(SUBSTITUTE(Y12,"€",""),"m",""))*1000000, VALUE(SUBSTITUTE(Y12,"€","")))) -> 200000
A13: Aiden O'Brien | B13: IRL | C13: FW | D13: Shelbourne FC | E13: 30 | F13: 1993 | G13: 8 | H13: 5 | I13: 459 | J13: 5.1 | K13: 1 | L13: 0 | M13: 1 | N13: 1 | O13: 0 | P13: 0 | Q13: 0 | R13: 0 | S13: 0.2 | T13: 0 | U13: 0.2 | V13: 0.2 | W13: 0.2 | X13: 1,80m | Y13: €600k | Z13: 0.75 | AA13: =IF(OR(ISNUMBER(SEARCH("DF", C13)), ISNUMBER(SEARCH("GK", C13))), "D", IF(ISNUMBER(SEARCH("MF", C13)), "M", IF(ISNUMBER(SEARCH("FW", C13)), "A","Unknown"))) -> A | AB13: =Z13 * IF(AA13="M", 2, IF(AA13="A", 4, 1)) -> 3 | AC13: =1/(AB13) -> 0.33333333 | AF13: =IF(RIGHT(Y13,1)="k", VALUE(SUBSTITUTE(SUBSTITUTE(Y13,"€",""),"k",""))*1000, IF(RIGHT(Y13,1)="m", VALUE(SUBSTITUTE(SUBSTITUTE(Y13,"€",""),"m",""))*1000000, VALUE(SUBSTITUTE(Y13,"€","")))) -> 600000
A14: Al Amin Kazeem | B14: ENG | C14: DF | D14: St Patrick's | E14: 21 | F14: 2002 | G14: 8 | H14: 2 | I14: 210 | J14: 2.3 | K14: 1 | L14: 0 | M14: 1 | N14: 1 | O14: 0 | P14: 0 | Q14: 1 | R14: 0 | S14: 0.43 | T14: 0 | U14: 0.43 | V14: 0.43 | W14: 0.43 | X14: 1,88m | Y14: €25k | Z14: 1.0277778 | AA14: =IF(OR(ISNUMBER(SEARCH("DF", C14)), ISNUMBER(SEARCH("GK", C14))), "D", IF(ISNUMBER(SEARCH("MF", C14)), "M", IF(ISNUMBER(SEARCH("FW", C14)), "A","Unknown"))) -> D | AB14: =Z14 * IF(AA14="M", 2, IF(AA14="A", 4, 1)) -> 1.0277778 | AC14: =1/(AB14) -> 0.97297297 | AF14: =IF(RIGHT(Y14,1)="k", VALUE(SUBSTITUTE(SUBSTITUTE(Y14,"€",""),"k",""))*1000, IF(RIGHT(Y14,1)="m", VALUE(SUBSTITUTE(SUBSTITUTE(Y14,"€",""),"m",""))*1000000, VALUE(SUBSTITUTE(Y14,"€","")))) -> 25000
A15: Al Amin Kazeem | B15: ENG | C15: DF | D15: Galway United | E15: 21 | F15: 2002 | G15: 20 | H15: 14 | I15: 1360 | J15: 15.1 | K15: 0 | L15: 0 | M15: 0 | N15: 0 | O15: 0 | P15: 0 | Q15: 4 | R15: 0 | S15: 0 | T15: 0 | U15: 0 | V15: 0 | W15: 0 | X15: 1,78m | Y15: €350k | Z15: 0.80555556 | AA15: =IF(OR(ISNUMBER(SEARCH("DF", C15)), ISNUMBER(SEARCH("GK", C15))), "D", IF(ISNUMBER(SEARCH("MF", C15)), "M", IF(ISNUMBER(SEARCH("FW", C15)), "A","Unknown"))) -> D | AB15: =Z15 * IF(AA15="M", 2, IF(AA15="A", 4, 1)) -> 0.80555556 | AC15: =1/(AB15) -> 1.2413793 | AF15: =IF(RIGHT(Y15,1)="k", VALUE(SUBSTITUTE(SUBSTITUTE(Y15,"€",""),"k",""))*1000, IF(RIGHT(Y15,1)="m", VALUE(SUBSTITUTE(SUBSTITUTE(Y15,"€",""),"m",""))*1000000, VALUE(SUBSTITUTE(Y15,"€","")))) -> 350000
A16: Alex Greive | B16: NZL | C16: FW | D16: Bohemian FC | E16: 24 | F16: 1999 | G16: 11 | H16: 3 | I16: 309 | J16: 3.4 | K16: 0 | L16: 0 | M16: 0 | N16: 0 | O16: 0 | P16: 0 | Q16: 0 | R16: 0 | S16: 0 | T16: 0 | U16: 0 | V16: 0 | W16: 0 | X16: 1,85m | Y16: €88k | Z16: 1.1944444 | AA16: =IF(OR(ISNUMBER(SEARCH("DF", C16)), ISNUMBER(SEARCH("GK", C16))), "D", IF(ISNUMBER(SEARCH("MF", C16)), "M", IF(ISNUMBER(SEARCH("FW", C16)), "A","Unknown"))) -> A | AB16: =Z16 * IF(AA16="M", 2, IF(AA16="A", 4, 1)) -> 4.7777778 | AC16: =1/(AB16) -> 0.20930233 | AF16: =IF(RIGHT(Y16,1)="k", VALUE(SUBSTITUTE(SUBSTITUTE(Y16,"€",""),"k",""))*1000, IF(RIGHT(Y16,1)="m", VALUE(SUBSTITUTE(SUBSTITUTE(Y16,"€",""),"m",""))*1000000, VALUE(SUBSTITUTE(Y16,"€","")))) -> 88000
A17: Alex Nolan | B17: IRL | C17: MF | D17: St Patrick's | E17: 20 | F17: 2003 | G17: 22 | H17: 7 | I17: 725 | J17: 8.1 | K17: 2 | L17: 0 | M17: 2 | N17: 2 | O17: 0 | P17: 0 | Q17: 3 | R17: 0 | S17: 0.25 | T17: 0 | U17: 0.25 | V17: 0.25 | W17: 0.25 | X17: 1.79 m | Y17: €19k | Z17: 1.0277778 | AA17: =IF(OR(ISNUMBER(SEARCH("DF", C17)), ISNUMBER(SEARCH("GK", C17))), "D", IF(ISNUMBER(SEARCH("MF", C17)), "M", IF(ISNUMBER(SEARCH("FW", C17)), "A","Unknown"))) -> M | AB17: =Z17 * IF(AA17="M", 2, IF(AA17="A", 4, 1)) -> 2.0555556 | AC17: =1/(AB17) -> 0.48648649 | AF17: =IF(RIGHT(Y17,1)="k", VALUE(SUBSTITUTE(SUBSTITUTE(Y17,"€",""),"k",""))*1000, IF(RIGHT(Y17,1)="m", VALUE(SUBSTITUTE(SUBSTITUTE(Y17,"€",""),"m",""))*1000000, VALUE(SUBSTITUTE(Y17,"€","")))) -> 19000
A18: Ali Coote | B18: SCO | C18: MF,FW | D18: Shelbourne FC | E18: 25 | F18: 1998 | G18: 13 | H18: 8 | I18: 669 | J18: 7.4 | K18: 1 | L18: 0 | M18: 1 | N18: 1 | O18: 0 | P18: 0 | Q18: 3 | R18: 0 | S18: 0.13 | T18: 0 | U18: 0.13 | V18: 0.13 | W18: 0.13 | X18: 1,86m | Y18: €300k | Z18: 0.75 | AA18: =IF(OR(ISNUMBER(SEARCH("DF", C18)), ISNUMBER(SEARCH("GK", C18))), "D", IF(ISNUMBER(SEARCH("MF", C18)), "M", IF(ISNUMBER(SEARCH("FW", C18)), "A","Unknown"))) -> M | AB18: =Z18 * IF(AA18="M", 2, IF(AA18="A", 4, 1)) -> 1.5 | AC18: =1/(AB18) -> 0.66666667 | AF18: =IF(RIGHT(Y18,1)="k", VALUE(SUBSTITUTE(SUBSTITUTE(Y18,"€",""),"k",""))*1000, IF(RIGHT(Y18,1)="m", VALUE(SUBSTITUTE(SUBSTITUTE(Y18,"€",""),"m",""))*1000000, VALUE(SUBSTITUTE(Y18,"€","")))) -> 300000
A19: Andre Wisdom | B19: ENG | C19: DF | D19: Derry City | E19: 30 | F19: 1993 | G19: 9 | H19: 9 | I19: 750 | J19: 8.3 | K19: 0 | L19: 0 | M19: 0 | N19: 0 | O19: 0 | P19: 0 | Q19: 1 | R19: 0 | S19: 0 | T19: 0 | U19: 0 | V19: 0 | W19: 0 | X19: 1,88m | Y19: €75k | Z19: 0.86111111 | AA19: =IF(OR(ISNUMBER(SEARCH("DF", C19)), ISNUMBER(SEARCH("GK", C19))), "D", IF(ISNUMBER(SEARCH("MF", C19)), "M", IF(ISNUMBER(SEARCH("FW", C19)), "A","Unknown"))) -> D | AB19: =Z19 * IF(AA19="M", 2, IF(AA19="A", 4, 1)) -> 0.86111111 | AC19: =1/(AB19) -> 1.1612903 | AF19: =IF(RIGHT(Y19,1)="k", VALUE(SUBSTITUTE(SUBSTITUTE(Y19,"€",""),"k",""))*1000, IF(RIGHT(Y19,1)="m", VALUE(SUBSTITUTE(SUBSTITUTE(Y19,"€",""),"m",""))*1000000, VALUE(SUBSTITUTE(Y19,"€","")))) -> 75000
A20: Andrew Quinn | B20: IRL | C20: DF | D20: Drogheda United | E20: 22 | F20: 2002 | G20: 27 | H20: 25 | I20: 2097 | J20: 23.3 | K20: 2 | L20: 1 | M20: 3 | N20: 2 | O20: 0 | P20: 0 | Q20: 2 | R20: 0 | S20: 0.09 | T20: 0.04 | U20: 0.13 | V20: 0.09 | W20: 0.13 | X20: 1,89m | Y20: €19k | Z20: 1.6111111 | AA20: =IF(OR(ISNUMBER(SEARCH("DF", C20)), ISNUMBER(SEARCH("GK", C20))), "D", IF(ISNUMBER(SEARCH("MF", C20)), "M", IF(ISNUMBER(SEARCH("FW", C20)), "A","Unknown"))) -> D | AB20: =Z20 * IF(AA20="M", 2, IF(AA20="A", 4, 1)) -> 1.6111111 | AC20: =1/(AB20) -> 0.62068966 | AF20: =IF(RIGHT(Y20,1)="k", VALUE(SUBSTITUTE(SUBSTITUTE(Y20,"€",""),"k",""))*1000, IF(RIGHT(Y20,1)="m", VALUE(SUBSTITUTE(SUBSTITUTE(Y20,"€",""),"m",""))*1000000, VALUE(SUBSTITUTE(Y20,"€","")))) -> 19000
A21: Andrew Wogan | B21: IRL | C21: GK | D21: Drogheda United | E21: 18 | F21: 2005 | G21: 19 | H21: 17 | I21: 1590 | J21: 17.7 | K21: 0 | L21: 1 | M21: 1 | N21: 0 | O21: 0 | P21: 0 | Q21: 1 | R21: 0 | S21: 0 | T21: 0.06 | U21: 0.06 | V21: 0 | W21: 0.06 | X21: 1,73m | Y21: €19k | Z21: 1.6111111 | AA21: =IF(OR(ISNUMBER(SEARCH("DF", C21)), ISNUMBER(SEARCH("GK", C21))), "D", IF(ISNUMBER(SEARCH("MF", C21)), "M", IF(ISNUMBER(SEARCH("FW", C21)), "A","Unknown"))) -> D | AB21: =Z21 * IF(AA21="M", 2, IF(AA21="A", 4, 1)) -> 1.6111111 | AC21: =1/(AB21) -> 0.62068966 | AF21: =IF(RIGHT(Y21,1)="k", VALUE(SUBSTITUTE(SUBSTITUTE(Y21,"€",""),"k",""))*1000, IF(RIGHT(Y21,1)="m", VALUE(SUBSTITUTE(SUBSTITUTE(Y21,"€",""),"m",""))*1000000, VALUE(SUBSTITUTE(Y21,"€","")))) -> 19000
... A97: Ellis Chapman | B97: ENG | C97: MF | D97: Sligo Rovers | E97: 23 | F97: 2001 | G97: 34 | H97: 33 | I97: 2764 | J97: 30.7 | K97: 9 | L97: 4 | M97: 13 | N97: 7 | O97: 2 | P97: 2 | Q97: 7 | R97: 0 | S97: 0.29 | T97: 0.13 | U97: 0.42 | V97: 0.23 | W97: 0.36 | X97: 1,90m | Y97: €65k | Z97: 1.4166667 | AA97: =IF(OR(ISNUMBER(SEARCH("DF", C97)), ISNUMBER(SEARCH("GK", C97))), "D", IF(ISNUMBER(SEARCH("MF", C97)), "M", IF(ISNUMBER(SEARCH("FW", C97)), "A","Unknown"))) -> M | AB97: =Z97 * IF(AA97="M", 2, IF(AA97="A", 4, 1)) -> 2.8333333 | AC97: =1/(AB97) -> 0.35294118 | AF97: =IF(RIGHT(Y97,1)="k", VALUE(SUBSTITUTE(SUBSTITUTE(Y97,"€",""),"k",""))*1000, IF(RIGHT(Y97,1)="m", VALUE(SUBSTITUTE(SUBSTITUTE(Y97,"€",""),"m",""))*1000000, VALUE(SUBSTITUTE(Y97,"€","")))) -> 65000
A98: Emre Topcu | C98: MF | D98: Drogheda United | E98: 18 | F98: 2005 | G98: 1 | H98: 0 | I98: 15 | J98: 0.2 | K98: 0 | L98: 0 | M98: 0 | N98: 0 | O98: 0 | P98: 0 | Q98: 0 | R98: 0 | S98: 0 | T98: 0 | U98: 0 | V98: 0 | W98: 0 | X98: 1.79 m | Y98: €52k | Z98: 1.6111111 | AA98: =IF(OR(ISNUMBER(SEARCH("DF", C98)), ISNUMBER(SEARCH("GK", C98))), "D", IF(ISNUMBER(SEARCH("MF", C98)), "M", IF(ISNUMBER(SEARCH("FW", C98)), "A","Unknown"))) -> M | AB98: =Z98 * IF(AA98="M", 2, IF(AA98="A", 4, 1)) -> 3.2222222 | AC98: =1/(AB98) -> 0.31034483 | AF98: =IF(RIGHT(Y98,1)="k", VALUE(SUBSTITUTE(SUBSTITUTE(Y98,"€",""),"k",""))*1000, IF(RIGHT(Y98,1)="m", VALUE(SUBSTITUTE(SUBSTITUTE(Y98,"€",""),"m",""))*1000000, VALUE(SUBSTITUTE(Y98,"€","")))) -> 52000
A99: Eoin Kenny | B99: NIR | C99: FW | D99: Dundalk FC | E99: 18 | F99: 2005 | G99: 25 | H99: 9 | I99: 864 | J99: 9.6 | K99: 2 | L99: 1 | M99: 3 | N99: 2 | O99: 0 | P99: 0 | Q99: 5 | R99: 0 | S99: 0.21 | T99: 0.1 | U99: 0.31 | V99: 0.21 | W99: 0.31 | X99: 1,91m | Y99: €150k | Z99: 1.3888889 | AA99: =IF(OR(ISNUMBER(SEARCH("DF", C99)), ISNUMBER(SEARCH("GK", C99))), "D", IF(ISNUMBER(SEARCH("MF", C99)), "M", IF(ISNUMBER(SEARCH("FW", C99)), "A","Unknown"))) -> A | AB99: =Z99 * IF(AA99="M", 2, IF(AA99="A", 4, 1)) -> 5.5555556 | AC99: =1/(AB99) -> 0.18 | AF99: =IF(RIGHT(Y99,1)="k", VALUE(SUBSTITUTE(SUBSTITUTE(Y99,"€",""),"k",""))*1000, IF(RIGHT(Y99,1)="m", VALUE(SUBSTITUTE(SUBSTITUTE(Y99,"€",""),"m",""))*1000000, VALUE(SUBSTITUTE(Y99,"€","")))) -> 150000
A100: Evan Caffrey | B100: IRL | C100: MF | D100: Shelbourne FC | E100: 20 | F100: 2003 | G100: 34 | H100: 17 | I100: 1822 | J100: 20.2 | K100: 3 | L100: 2 | M100: 5 | N100: 3 | O100: 0 | P100: 0 | Q100: 4 | R100: 0 | S100: 0.15 | T100: 0.1 | U100: 0.25 | V100: 0.15 | W100: 0.25 | X100: 1,78m | Y100: €117k | Z100: 0.75 | AA100: =IF(OR(ISNUMBER(SEARCH("DF", C100)), ISNUMBER(SEARCH("GK", C100))), "D", IF(ISNUMBER(SEARCH("MF", C100)), "M", IF(ISNUMBER(SEARCH("FW", C100)), "A","Unknown"))) -> M | AB100: =Z100 * IF(AA100="M", 2, IF(AA100="A", 4, 1)) -> 1.5 | AC100: =1/(AB100) -> 0.66666667 | AF100: =IF(RIGHT(Y100,1)="k", VALUE(SUBSTITUTE(SUBSTITUTE(Y100,"€",""),"k",""))*1000, IF(RIGHT(Y100,1)="m", VALUE(SUBSTITUTE(SUBSTITUTE(Y100,"€",""),"m",""))*1000000, VALUE(SUBSTITUTE(Y100,"€","")))) -> 117000
A101: Evan Haddock | B101: IRL | C101: MF | D101: Drogheda United | E101: 18 | F101: 2005 | G101: 1 | H101: 0 | I101: 5 | J101: 0.1 | K101: 0 | L101: 0 | M101: 0 | N101: 0 | O101: 0 | P101: 0 | Q101: 0 | R101: 0 | S101: 0 | T101: 0 | U101: 0 | V101: 0 | W101: 0 | X101: 1.79 m | Y101: €52k | Z101: 1.6111111 | AA101: =IF(OR(ISNUMBER(SEARCH("DF", C101)), ISNUMBER(SEARCH("GK", C101))), "D", IF(ISNUMBER(SEARCH("MF", C101)), "M", IF(ISNUMBER(SEARCH("FW", C101)), "A","Unknown"))) -> M | AB101: =Z101 * IF(AA101="M", 2, IF(AA101="A", 4, 1)) -> 3.2222222 | AC101: =1/(AB101) -> 0.31034483 | AF101: =IF(RIGHT(Y101,1)="k", VALUE(SUBSTITUTE(SUBSTITUTE(Y101,"€",""),"k",""))*1000, IF(RIGHT(Y101,1)="m", VALUE(SUBSTITUTE(SUBSTITUTE(Y101,"€",""),"m",""))*1000000, VALUE(SUBSTITUTE(Y101,"€","")))) -> 52000
A102: Evan Weir | B102: IRL | C102: DF,MF | D102: Drogheda United | E102: 21 | F102: 2002 | G102: 19 | H102: 19 | I102: 1637 | J102: 18.2 | K102: 4 | L102: 2 | M102: 6 | N102: 4 | O102: 0 | P102: 0 | Q102: 5 | R102: 0 | S102: 0.22 | T102: 0.11 | U102: 0.33 | V102: 0.22 | W102: 0.33 | X102: 1.79 m | Y102: €65k | Z102: 1.6111111 | AA102: =IF(OR(ISNUMBER(SEARCH("DF", C102)), ISNUMBER(SEARCH("GK", C102))), "D", IF(ISNUMBER(SEARCH("MF", C102)), "M", IF(ISNUMBER(SEARCH("FW", C102)), "A","Unknown"))) -> D | AB102: =Z102 * IF(AA102="M", 2, IF(AA102="A", 4, 1)) -> 1.6111111 | AC102: =1/(AB102) -> 0.62068966 | AF102: =IF(RIGHT(Y102,1)="k", VALUE(SUBSTITUTE(SUBSTITUTE(Y102,"€",""),"k",""))*1000, IF(RIGHT(Y102,1)="m", VALUE(SUBSTITUTE(SUBSTITUTE(Y102,"€",""),"m",""))*1000000, VALUE(SUBSTITUTE(Y102,"€","")))) -> 65000
A103: Fabrice Hartmann | B103: GER | C103: MF,FW | D103: Sligo Rovers | E103: 22 | F103: 2001 | G103: 21 | H103: 19 | I103: 1390 | J103: 15.4 | K103: 4 | L103: 3 | M103: 7 | N103: 4 | O103: 0 | P103: 0 | Q103: 4 | R103: 0 | S103: 0.26 | T103: 0.19 | U103: 0.45 | V103: 0.26 | W103: 0.45 | X103: 1,86m | Y103: €39k | Z103: 1.4166667 | AA103: =IF(OR(ISNUMBER(SEARCH("DF", C103)), ISNUMBER(SEARCH("GK", C103))), "D", IF(ISNUMBER(SEARCH("MF", C103)), "M", IF(ISNUMBER(SEARCH("FW", C103)), "A","Unknown"))) -> M | AB103: =Z103 * IF(AA103="M", 2, IF(AA103="A", 4, 1)) -> 2.8333333 | AC103: =1/(AB103) -> 0.35294118 | AF103: =IF(RIGHT(Y103,1)="k", VALUE(SUBSTITUTE(SUBSTITUTE(Y103,"€",""),"k",""))*1000, IF(RIGHT(Y103,1)="m", VALUE(SUBSTITUTE(SUBSTITUTE(Y103,"€",""),"m",""))*1000000, VALUE(SUBSTITUTE(Y103,"€","")))) -> 39000
A104: Felix Goddard | B104: ENG | C104: GK | D104: Dundalk FC | E104: 19 | F104: 2004 | G104: 6 | H104: 6 | I104: 540 | J104: 6 | K104: 0 | L104: 0 | M104: 0 | N104: 0 | O104: 0 | P104: 0 | Q104: 0 | R104: 0 | S104: 0 | T104: 0 | U104: 0 | V104: 0 | W104: 0 | X104: 1,95m | Y104: €72k | Z104: 1.3888889 | AA104: =IF(OR(ISNUMBER(SEARCH("DF", C104)), ISNUMBER(SEARCH("GK", C104))), "D", IF(ISNUMBER(SEARCH("MF", C104)), "M", IF(ISNUMBER(SEARCH("FW", C104)), "A","Unknown"))) -> D | AB104: =Z104 * IF(AA104="M", 2, IF(AA104="A", 4, 1)) -> 1.3888889 | AC104: =1/(AB104) -> 0.72 | AF104: =IF(RIGHT(Y104,1)="k", VALUE(SUBSTITUTE(SUBSTITUTE(Y104,"€",""),"k",""))*1000, IF(RIGHT(Y104,1)="m", VALUE(SUBSTITUTE(SUBSTITUTE(Y104,"€",""),"m",""))*1000000, VALUE(SUBSTITUTE(Y104,"€","")))) -> 72000
A105: Filip Piszczek | B105: POL | C105: FW | D105: Bohemian FC | E105: 28 | F105: 1995 | G105: 21 | H105: 4 | I105: 692 | J105: 7.7 | K105: 2 | L105: 1 | M105: 3 | N105: 2 | O105: 0 | P105: 0 | Q105: 9 | R105: 0 | S105: 0.26 | T105: 0.13 | U105: 0.39 | V105: 0.26 | W105: 0.39 | X105: 1,75m | Y105: €25k | Z105: 1.1944444 | AA105: =IF(OR(ISNUMBER(SEARCH("DF", C105)), ISNUMBER(SEARCH("GK", C105))), "D", IF(ISNUMBER(SEARCH("MF", C105)), "M", IF(ISNUMBER(SEARCH("FW", C105)), "A","Unknown"))) -> A | AB105: =Z105 * IF(AA105="M", 2, IF(AA105="A", 4, 1)) -> 4.7777778 | AC105: =1/(AB105) -> 0.20930233 | AF105: =IF(RIGHT(Y105,1)="k", VALUE(SUBSTITUTE(SUBSTITUTE(Y105,"€",""),"k",""))*1000, IF(RIGHT(Y105,1)="m", VALUE(SUBSTITUTE(SUBSTITUTE(Y105,"€",""),"m",""))*1000000, VALUE(SUBSTITUTE(Y105,"€","")))) -> 25000
A106: Francely Lomboto | B106: IRL | C106: FW | D106: Galway United | E106: 23 | F106: 2000 | G106: 20 | H106: 2 | I106: 417 | J106: 4.6 | K106: 1 | L106: 0 | M106: 1 | N106: 1 | O106: 0 | P106: 1 | Q106: 1 | R106: 0 | S106: 0.22 | T106: 0 | U106: 0.22 | V106: 0.22 | W106: 0.22 | X106: 1.79 m | Y106: €25k | Z106: 0.80555556 | AA106: =IF(OR(ISNUMBER(SEARCH("DF", C106)), ISNUMBER(SEARCH("GK", C106))), "D", IF(ISNUMBER(SEARCH("MF", C106)), "M", IF(ISNUMBER(SEARCH("FW", C106)), "A","Unknown"))) -> A | AB106: =Z106 * IF(AA106="M", 2, IF(AA106="A", 4, 1)) -> 3.2222222 | AC106: =1/(AB106) -> 0.31034483 | AF106: =IF(RIGHT(Y106,1)="k", VALUE(SUBSTITUTE(SUBSTITUTE(Y106,"€",""),"k",""))*1000, IF(RIGHT(Y106,1)="m", VALUE(SUBSTITUTE(SUBSTITUTE(Y106,"€",""),"m",""))*1000000, VALUE(SUBSTITUTE(Y106,"€","")))) -> 25000
A107: Frantz Pierrot | B107: HAI | C107: FW | D107: Drogheda United | E107: 24 | F107: 1999 | G107: 31 | H107: 24 | I107: 2064 | J107: 22.9 | K107: 10 | L107: 1 | M107: 11 | N107: 9 | O107: 1 | P107: 1 | Q107: 6 | R107: 1 | S107: 0.44 | T107: 0.04 | U107: 0.48 | V107: 0.39 | W107: 0.44 | X107: 1.79 m | Y107: €50k | Z107: 1.6111111 | AA107: =IF(OR(ISNUMBER(SEARCH("DF", C107)), ISNUMBER(SEARCH("GK", C107))), "D", IF(ISNUMBER(SEARCH("MF", C107)), "M", IF(ISNUMBER(SEARCH("FW", C107)), "A","Unknown"))) -> A | AB107: =Z107 * IF(AA107="M", 2, IF(AA107="A", 4, 1)) -> 6.4444444 | AC107: =1/(AB107) -> 0.15517241 | AF107: =IF(RIGHT(Y107,1)="k", VALUE(SUBSTITUTE(SUBSTITUTE(Y107,"€",""),"k",""))*1000, IF(RIGHT(Y107,1)="m", VALUE(SUBSTITUTE(SUBSTITUTE(Y107,"€",""),"m",""))*1000000, VALUE(SUBSTITUTE(Y107,"€","")))) -> 50000
A108: Gareth McElroy | B108: IRL | C108: DF | D108: Sligo Rovers | E108: 16 | F108: 2007 | G108: 4 | H108: 4 | I108: 358 | J108: 4 | K108: 0 | L108: 0 | M108: 0 | N108: 0 | O108: 0 | P108: 0 | Q108: 2 | R108: 0 | S108: 0 | T108: 0 | U108: 0 | V108: 0 | W108: 0 | X108: 1,75m | Y108: €86k | Z108: 1.4166667 | AA108: =IF(OR(ISNUMBER(SEARCH("DF", C108)), ISNUMBER(SEARCH("GK", C108))), "D", IF(ISNUMBER(SEARCH("MF", C108)), "M", IF(ISNUMBER(SEARCH("FW", C108)), "A","Unknown"))) -> D | AB108: =Z108 * IF(AA108="M", 2, IF(AA108="A", 4, 1)) -> 1.4166667 | AC108: =1/(AB108) -> 0.70588235 | AF108: =IF(RIGHT(Y108,1)="k", VALUE(SUBSTITUTE(SUBSTITUTE(Y108,"€",""),"k",""))*1000, IF(RIGHT(Y108,1)="m", VALUE(SUBSTITUTE(SUBSTITUTE(Y108,"€",""),"m",""))*1000000, VALUE(SUBSTITUTE(Y108,"€","")))) -> 86000
A109: Garry Buckley | B109: IRL | C109: DF,MF | D109: Galway United | E109: 30 | F109: 1993 | G109: 21 | H109: 18 | I109: 1649 | J109: 18.3 | K109: 0 | L109: 0 | M109: 0 | N109: 0 | O109: 0 | P109: 0 | Q109: 4 | R109: 0 | S109: 0 | T109: 0 | U109: 0 | V109: 0 | W109: 0 | X109: 1,80m | Y109: €275k | Z109: 0.80555556 | AA109: =IF(OR(ISNUMBER(SEARCH("DF", C109)), ISNUMBER(SEARCH("GK", C109))), "D", IF(ISNUMBER(SEARCH("MF", C109)), "M", IF(ISNUMBER(SEARCH("FW", C109)), "A","Unknown"))) -> D | AB109: =Z109 * IF(AA109="M", 2, IF(AA109="A", 4, 1)) -> 0.80555556 | AC109: =1/(AB109) -> 1.2413793 | AF109: =IF(RIGHT(Y109,1)="k", VALUE(SUBSTITUTE(SUBSTITUTE(Y109,"€",""),"k",""))*1000, IF(RIGHT(Y109,1)="m", VALUE(SUBSTITUTE(SUBSTITUTE(Y109,"€",""),"m",""))*1000000, VALUE(SUBSTITUTE(Y109,"€","")))) -> 275000
A110: Gary Deegan | B110: IRL | C110: MF | D110: Drogheda United | E110: 36 | F110: 1987 | G110: 22 | H110: 18 | I110: 1669 | J110: 18.5 | K110: 0 | L110: 1 | M110: 1 | N110: 0 | O110: 0 | P110: 0 | Q110: 6 | R110: 0 | S110: 0 | T110: 0.05 | U110: 0.05 | V110: 0 | W110: 0.05 | X110: 1,85m | Y110: €75k | Z110: 1.6111111 | AA110: =IF(OR(ISNUMBER(SEARCH("DF", C110)), ISNUMBER(SEARCH("GK", C110))), "D", IF(ISNUMBER(SEARCH("MF", C110)), "M", IF(ISNUMBER(SEARCH("FW", C110)), "A","Unknown"))) -> M | AB110: =Z110 * IF(AA110="M", 2, IF(AA110="A", 4, 1)) -> 3.2222222 | AC110: =1/(AB110) -> 0.31034483 | AF110: =IF(RIGHT(Y110,1)="k", VALUE(SUBSTITUTE(SUBSTITUTE(Y110,"€",""),"k",""))*1000, IF(RIGHT(Y110,1)="m", VALUE(SUBSTITUTE(SUBSTITUTE(Y110,"€",""),"m",""))*1000000, VALUE(SUBSTITUTE(Y110,"€","")))) -> 75000
... A133: James Bolger | B133: IRL | C133: DF | D133: Drogheda United | E133: 23 | F133: 2000 | G133: 12 | H133: 12 | I133: 1031 | J133: 11.5 | K133: 0 | L133: 0 | M133: 0 | N133: 0 | O133: 0 | P133: 0 | Q133: 3 | R133: 0 | S133: 0 | T133: 0 | U133: 0 | V133: 0 | W133: 0 | X133: 1,90m | Y133: €88k | Z133: 1.6111111 | AA133: =IF(OR(ISNUMBER(SEARCH("DF", C133)), ISNUMBER(SEARCH("GK", C133))), "D", IF(ISNUMBER(SEARCH("MF", C133)), "M", IF(ISNUMBER(SEARCH("FW", C133)), "A","Unknown"))) -> D | AB133: =Z133 * IF(AA133="M", 2, IF(AA133="A", 4, 1)) -> 1.6111111 | AC133: =1/(AB133) -> 0.62068966 | AF133: =IF(RIGHT(Y133,1)="k", VALUE(SUBSTITUTE(SUBSTITUTE(Y133,"€",""),"k",""))*1000, IF(RIGHT(Y133,1)="m", VALUE(SUBSTITUTE(SUBSTITUTE(Y133,"€",""),"m",""))*1000000, VALUE(SUBSTITUTE(Y133,"€","")))) -> 88000
A134: James Byrne | B134: #VALUE! | C134: MF | D134: Drogheda United | G134: 1 | H134: 0 | I134: 20 | J134: 0.2 | K134: 0 | L134: 0 | M134: 0 | N134: 0 | O134: 0 | P134: 0 | Q134: 0 | R134: 0 | S134: 0 | T134: 0 | U134: 0 | V134: 0 | W134: 0 | X134: 1,75m | Y134: €100k | Z134: 1.6111111 | AA134: =IF(OR(ISNUMBER(SEARCH("DF", C134)), ISNUMBER(SEARCH("GK", C134))), "D", IF(ISNUMBER(SEARCH("MF", C134)), "M", IF(ISNUMBER(SEARCH("FW", C134)), "A","Unknown"))) -> M | AB134: =Z134 * IF(AA134="M", 2, IF(AA134="A", 4, 1)) -> 3.2222222 | AC134: =1/(AB134) -> 0.31034483 | AF134: =IF(RIGHT(Y134,1)="k", VALUE(SUBSTITUTE(SUBSTITUTE(Y134,"€",""),"k",""))*1000, IF(RIGHT(Y134,1)="m", VALUE(SUBSTITUTE(SUBSTITUTE(Y134,"€",""),"m",""))*1000000, VALUE(SUBSTITUTE(Y134,"€","")))) -> 100000
A135: James Clarke | B135: IRL | C135: MF,FW | D135: Bohemian FC | E135: 23 | F135: 2001 | G135: 34 | H135: 26 | I135: 2295 | J135: 25.5 | K135: 4 | L135: 1 | M135: 5 | N135: 4 | O135: 0 | P135: 0 | Q135: 7 | R135: 0 | S135: 0.16 | T135: 0.04 | U135: 0.2 | V135: 0.16 | W135: 0.2 | X135: 1,83m | Y135: €20k | Z135: 1.1944444 | AA135: =IF(OR(ISNUMBER(SEARCH("DF", C135)), ISNUMBER(SEARCH("GK", C135))), "D", IF(ISNUMBER(SEARCH("MF", C135)), "M", IF(ISNUMBER(SEARCH("FW", C135)), "A","Unknown"))) -> M | AB135: =Z135 * IF(AA135="M", 2, IF(AA135="A", 4, 1)) -> 2.3888889 | AC135: =1/(AB135) -> 0.41860465 | AF135: =IF(RIGHT(Y135,1)="k", VALUE(SUBSTITUTE(SUBSTITUTE(Y135,"€",""),"k",""))*1000, IF(RIGHT(Y135,1)="m", VALUE(SUBSTITUTE(SUBSTITUTE(Y135,"€",""),"m",""))*1000000, VALUE(SUBSTITUTE(Y135,"€","")))) -> 20000
A136: James Gullan | B136: SCO | C136: FW | D136: Dundalk FC | E136: 24 | F136: 1999 | G136: 31 | H136: 24 | I136: 2079 | J136: 23.1 | K136: 6 | L136: 1 | M136: 7 | N136: 5 | O136: 1 | P136: 1 | Q136: 5 | R136: 0 | S136: 0.26 | T136: 0.04 | U136: 0.3 | V136: 0.22 | W136: 0.26 | X136: 1,88m | Y136: €117k | Z136: 1.3888889 | AA136: =IF(OR(ISNUMBER(SEARCH("DF", C136)), ISNUMBER(SEARCH("GK", C136))), "D", IF(ISNUMBER(SEARCH("MF", C136)), "M", IF(ISNUMBER(SEARCH("FW", C136)), "A","Unknown"))) -> A | AB136: =Z136 * IF(AA136="M", 2, IF(AA136="A", 4, 1)) -> 5.5555556 | AC136: =1/(AB136) -> 0.18 | AF136: =IF(RIGHT(Y136,1)="k", VALUE(SUBSTITUTE(SUBSTITUTE(Y136,"€",""),"k",""))*1000, IF(RIGHT(Y136,1)="m", VALUE(SUBSTITUTE(SUBSTITUTE(Y136,"€",""),"m",""))*1000000, VALUE(SUBSTITUTE(Y136,"€","")))) -> 117000
A137: James McManus | B137: IRL | C137: MF | D137: Bohemian FC | E137: 18 | F137: 2005 | G137: 11 | H137: 8 | I137: 682 | J137: 7.6 | K137: 0 | L137: 0 | M137: 0 | N137: 0 | O137: 0 | P137: 0 | Q137: 2 | R137: 0 | S137: 0 | T137: 0 | U137: 0 | V137: 0 | W137: 0 | X137: 1,75m | Y137: €75k | Z137: 1.1944444 | AA137: =IF(OR(ISNUMBER(SEARCH("DF", C137)), ISNUMBER(SEARCH("GK", C137))), "D", IF(ISNUMBER(SEARCH("MF", C137)), "M", IF(ISNUMBER(SEARCH("FW", C137)), "A","Unknown"))) -> M | AB137: =Z137 * IF(AA137="M", 2, IF(AA137="A", 4, 1)) -> 2.3888889 | AC137: =1/(AB137) -> 0.41860465 | AF137: =IF(RIGHT(Y137,1)="k", VALUE(SUBSTITUTE(SUBSTITUTE(Y137,"€",""),"k",""))*1000, IF(RIGHT(Y137,1)="m", VALUE(SUBSTITUTE(SUBSTITUTE(Y137,"€",""),"m",""))*1000000, VALUE(SUBSTITUTE(Y137,"€","")))) -> 75000
...

Sheet Teams
A1: Squad (corrected for player data) | B1: Goals Conceded
A2: Shelbourne | B2: 27
A3: Shamrock Rovers | B3: 35
A4: St Patrick's | B4: 37
A5: Derry City | B5: 31
A6: Galway United | B6: 29
A7: Sligo Rovers | B7: 51
A8: Waterford FC | B8: 47
A9: Bohemians | B9: 43
A10: Drogheda United | B10: 58
A11: Dundalk FC | B11: 50

Sheet 2024 league results
E1: Playing Time | I1: Performance | Q1: Per 90 Minutes | V1: Finnances
A2: Squad | B2: # Pl | C2: Age | D2: Poss | E2: MP | F2: Starts | G2: Min | H2: 90s | I2: Gls | J2: Ast | K2: G+A | L2: G-PK | M2: PK | N2: PKatt | O2: CrdY | P2: CrdR | Q2: Gls | R2: Ast | S2: G+A | T2: G-PK | U2: G+A-PK | V2: Squad Size | W2: ø age | X2: Foreigners | Y2: ø market value | Z2: Total market value
A3: Bohemian FC | B3: 33 | C3: 24.9 | D3: 52.2 | E3: 36 | F3: 396 | G3: 3240 | H3: 36 | I3: 37 | J3: 26 | K3: 63 | L3: 33 | M3: 4 | N3: 8 | O3: 106 | P3: 2 | Q3: 1.03 | R3: 0.72 | S3: 1.75 | T3: 0.92 | U3: 1.64 | V3: 55 | W3: 21.5 | X3: 18 | Y3: €117k | Z3: €6.45m
A4: Derry City | B4: 27 | C4: 27.3 | D4: 56 | E4: 36 | F4: 396 | G4: 3240 | H4: 36 | I4: 46 | J4: 31 | K4: 77 | L4: 39 | M4: 7 | N4: 7 | O4: 74 | P4: 1 | Q4: 1.28 | R4: 0.86 | S4: 2.14 | T4: 1.08 | U4: 1.94 | V4: 39 | W4: 23.4 | X4: 19 | Y4: €117k | Z4: €4.55m
A5: Drogheda United | B5: 30 | C5: 25.1 | D5: 38.9 | E5: 36 | F5: 396 | G5: 3240 | H5: 36 | I5: 39 | J5: 21 | K5: 60 | L5: 35 | M5: 4 | N5: 5 | O5: 92 | P5: 5 | Q5: 1.08 | R5: 0.58 | S5: 1.67 | T5: 0.97 | U5: 1.56 | V5: 43 | W5: 21.3 | X5: 10 | Y5: €19k | Z5: €825k
A6: Dundalk FC | B6: 38 | C6: 24.8 | D6: 48 | E6: 36 | F6: 396 | G6: 3240 | H6: 36 | I6: 23 | J6: 16 | K6: 39 | L6: 21 | M6: 2 | N6: 2 | O6: 91 | P6: 3 | Q6: 0.64 | R6: 0.44 | S6: 1.08 | T6: 0.58 | U6: 1.03 | V6: 70 | W6: 21.5 | X6: 29 | Y6: €65k | Z6: €4.54m
A7: Galway United | B7: 28 | C7: 28.3 | D7: 39.3 | E7: 36 | F7: 396 | G7: 3240 | H7: 36 | I7: 32 | J7: 21 | K7: 53 | L7: 31 | M7: 1 | N7: 2 | O7: 76 | P7: 3 | Q7: 0.89 | R7: 0.58 | S7: 1.47 | T7: 0.86 | U7: 1.44 | V7: 35 | W7: 24.4 | X7: 10 | Y7: €39k | Z7: €1.35m
A8: Shamrock Rovers | B8: 31 | C8: 27 | D8: 62.4 | E8: 36 | F8: 396 | G8: 3240 | H8: 36 | I8: 49 | J8: 39 | K8: 88 | L8: 49 | M8: 0 | N8: 2 | O8: 99 | P8: 2 | Q8: 1.36 | R8: 1.08 | S8: 2.44 | T8: 1.36 | U8: 2.44 | V8: 61 | W8: 22.3 | X8: 8 | Y8: €86k | Z8: €5.28m
A9: Shelbourne FC | B9: 28 | C9: 25.9 | D9: 53.9 | E9: 36 | F9: 396 | G9: 3240 | H9: 36 | I9: 39 | J9: 26 | K9: 65 | L9: 34 | M9: 5 | N9: 6 | O9: 112 | P9: 5 | Q9: 1.08 | R9: 0.72 | S9: 1.81 | T9: 0.94 | U9: 1.67 | V9: 52 | W9: 21.2 | X9: 7 | Y9: €52k | Z9: €2.70m
A10: Sligo Rovers | B10: 28 | C10: 23.3 | D10: 47.7 | E10: 36 | F10: 396 | G10: 3240 | H10: 36 | I10: 40 | J10: 28 | K10: 68 | L10: 38 | M10: 2 | N10: 2 | O10: 97 | P10: 5 | Q10: 1.11 | R10: 0.78 | S10: 1.89 | T10: 1.06 | U10: 1.83 | V10: 36 | W10: 20.7 | X10: 12 | Y10: €72k | Z10: €2.59m
A11: St Patrick's | B11: 27 | C11: 25.2 | D11: 52.8 | E11: 36 | F11: 396 | G11: 3240 | H11: 36 | I11: 51 | J11: 35 | K11: 86 | L11: 46 | M11: 5 | N11: 5 | O11: 79 | P11: 0 | Q11: 1.42 | R11: 0.97 | S11: 2.39 | T11: 1.28 | U11: 2.25 | V11: 64 | W11: 21.2 | X11: 17 | Y11: €88k | Z11: €5.65m
A12: Waterford United | B12: 26 | C12: 24.5 | D12: 49.5 | E12: 36 | F12: 396 | G12: 3240 | H12: 36 | I12: 42 | J12: 25 | K12: 67 | L12: 40 | M12: 2 | N12: 3 | O12: 87 | P12: 2 | Q12: 1.17 | R12: 0.69 | S12: 1.86 | T12: 1.11 | U12: 1.81 | V12: 47 | W12: 20.6 | X12: 17 | Y12: €20k | Z12: €925k
J14: Mean Attacking contribution of an attaker | K14: 11 | O14: Mean Attacking contribution of an attaker (Relative performance) | Q14: # | R14: Club | U14: W | V14: D | W14: L | X14: Goals | Y14: GD | Z14: Pts | AA14: Conceeded
J15: (Goals + Assists) + PK = aplpha_A | O15: (aplpha_A) / Team average | Q15: 1 | S15: Shelbourne | T15: 36 | U15: 17 | V15: 12 | W15: 7 | X15: 1.6854167 | Y15: 13 | Z15: 63 | AA15: 27
J16: A player whos scores alot of goals and assists. we double count PK as it shows an involved player | Q16: 2 | S16: Shamrock Rovers | T16: 36 | U16: 17 | V16: 10 | W16: 9 | X16: 2.1076389 | Y16: 15 | Z16: 61 | AA16: 35
Q17: 3 | S17: St. Pat's | T17: 36 | U17: 17 | V17: 8 | W17: 11 | X17: 2.1506944 | Y17: 14 | Z17: 59 | AA17: 37
J18: Mean Attacking contribution of an defender | O18: Mean Attacking contribution of an defender (Relative performance) | Q18: 4 | S18: Derry City | T18: 36 | U18: 14 | V18: 13 | W18: 9 | X18: 2.0215278 | Y18: 17 | Z18: 55 | AA18: 31
J19: (Goals + Assists) + PK = alpha_D | O19: (aplpha_D) / Team average | Q19: 5 | S19: Galway United | T19: 36 | U19: 13 | V19: 13 | W19: 10 | X19: 1.3951389 | Y19: 4 | Z19: 52 | AA19: 29
J20: A player whos scores alot of goals and assists. we double count PK as it shows an involved player | Q20: 6 | S20: Sligo Rovers | T20: 36 | U20: 13 | V20: 10 | W20: 13 | X20: 1.7020833 | Y20: -11 | Z20: 49 | AA20: 51
Q21: 7 | S21: Waterford FC | T21: 36 | U21: 13 | V21: 6 | W21: 17 | X21: 1.8243056 | Y21: -4 | Z21: 45 | AA21: 47
J22: Mean defending contribution of a attacker | O22: Mean defending contribution of a attacker (Relative performance) | Q22: 8 | S22: Bohemians | T22: 36 | U22: 10 | V22: 12 | W22: 14 | X22: 1.6548611 | Y22: -4 | Z22: 42 | AA22: 43
J23: (Height * (1+YC) ) - RC = beta_A | O23: (beta_A) / Team average | Q23: 9 | S23: Drogheda United | T23: 36 | U23: 7 | V23: 13 | W23: 16 | X23: 1.7486111 | Y23: -17 | Z23: 34 | AA23: 58
J24: A player who is tall makes alot of yellow card tackles but no reds | Q24: 10 | S24: Dundalk FC | T24: 36 | U24: 5 | V24: 11 | W24: 20 | X24: 0.99305556 | Y24: -27 | Z24: 26 | AA24: 50
J26: Mean defending contribution of a defender | O26: Mean defending contribution of a defender (Relative performance)
J27: (Height * (1+YC) ) - RC = beta_D | O27: (beta_D) / Team average
J28: A player who is tall makes alot of yellow card tackles but no reds
J31: Mean Attacking contribution of an attaker (Relative Cost performance)
J32: ((aplpha_A) / Team average ) * Player Valaue
J35: Mean Attacking contribution of an defender (Relative Cost performance)
J36: ((aplpha_D) / Team average ) * Player Valaue
J39: Mean defending contribution of a attacker (Relative Cost performance)
J40: ((beta_A) / Team average ) * Player Valaue
J43: Mean defending contribution of a defender (Relative Cost performance)
J44: ((beta_D) / Team average ) * Player Valaue
B61: Squad | C61: ø age | D61: Foreigners | E61: ø market value | F61: Total market value
A62: Bohemian Football Club | B62: 55 | C62: 21.5 | D62: 18 | E62: €117k | F62: €6.45m
A63: Derry City | B63: 39 | C63: 23.4 | D63: 19 | E63: €117k | F63: €4.55m
A64: Drogheda United FC | B64: 43 | C64: 21.3 | D64: 10 | E64: €19k | F64: €825k
A65: Dundalk FC | B65: 70 | C65: 21.5 | D65: 29 | E65: €65k | F65: €4.54m
A66: Galway United FC | B66: 35 | C66: 24.4 | D66: 10 | E66: €39k | F66: €1.35m
...

Sheet Player Results
A1: Player Standard Stats 2024 League of Ireland Premier Division
H5: Playing Time | L5: Performance | T5: Per 90 Minutes
A6: Rk | B6: Player | C6: Nation | D6: Pos | E6: Squad | F6: Age | G6: Born | H6: MP | I6: Starts | J6: Min | K6: 90s | L6: Gls | M6: Ast | N6: G+A | O6: G-PK | P6: PK | Q6: PKatt | R6: CrdY | S6: CrdR | T6: Gls | U6: Ast | V6: G+A | W6: G-PK | X6: G+A-PK | Y6: Matches
A7: 1 | B7: Elicha Ahui | C7: ENG | D7: MF,DF | E7: Drogheda United | F7: 20 | G7: 2003 | H7: 14 | I7: 14 | J7: 1101 | K7: 12.2 | L7: 1 | M7: 0 | N7: 1 | O7: 1 | P7: 0 | Q7: 0 | R7: 4 | S7: 0 | T7: 0.08 | U7: 0 | V7: 0.08 | W7: 0.08 | X7: 0.08 | Y7: Matches
A8: 2 | B8: Romeo Akachukwu | C8: IRL | D8: MF | E8: Waterford United | F8: 17 | G8: 2006 | H8: 7 | I8: 0 | J8: 90 | K8: 1 | L8: 0 | M8: 0 | N8: 0 | O8: 0 | P8: 0 | Q8: 0 | R8: 0 | S8: 0 | T8: 0 | U8: 0 | V8: 0 | W8: 0 | X8: 0 | Y8: Matches
A9: 3 | B9: James Akintunde | C9: ENG | D9: FW,MF | E9: Bohemian FC | F9: 27 | G9: 1996 | H9: 27 | I9: 19 | J9: 1793 | K9: 19.9 | L9: 5 | M9: 2 | N9: 7 | O9: 5 | P9: 0 | Q9: 1 | R9: 1 | S9: 0 | T9: 0.25 | U9: 0.1 | V9: 0.35 | W9: 0.25 | X9: 0.35 | Y9: Matches
A10: 4 | B10: Al Amin Kazeem | C10: ENG | D10: DF | E10: St Patrick's | F10: 21 | G10: 2002 | H10: 8 | I10: 2 | J10: 210 | K10: 2.3 | L10: 1 | M10: 0 | N10: 1 | O10: 1 | P10: 0 | Q10: 0 | R10: 1 | S10: 0 | T10: 0.43 | U10: 0 | V10: 0.43 | W10: 0.43 | X10: 0.43 | Y10: Matches
A11: 5 | B11: Al Amin Kazeem | C11: ENG | D11: DF | E11: Galway United | F11: 21 | G11: 2002 | H11: 20 | I11: 14 | J11: 1360 | K11: 15.1 | L11: 0 | M11: 0 | N11: 0 | O11: 0 | P11: 0 | Q11: 0 | R11: 4 | S11: 0 | T11: 0 | U11: 0 | V11: 0 | W11: 0 | X11: 0 | Y11: Matches
A12: 6 | B12: Pádraig Amond | C12: IRL | D12: FW | E12: Waterford United | F12: 35 | G12: 1988 | H12: 36 | I12: 36 | J12: 3230 | K12: 35.9 | L12: 14 | M12: 2 | N12: 16 | O12: 12 | P12: 2 | Q12: 3 | R12: 1 | S12: 0 | T12: 0.39 | U12: 0.06 | V12: 0.45 | W12: 0.33 | X12: 0.39 | Y12: Matches
A13: 7 | B13: Joseph Anang | C13: GHA | D13: GK | E13: St Patrick's | F13: 23 | G13: 2000 | H13: 12 | I13: 12 | J13: 1080 | K13: 12 | L13: 0 | M13: 0 | N13: 0 | O13: 0 | P13: 0 | Q13: 0 | R13: 0 | S13: 0 | T13: 0 | U13: 0 | V13: 0 | W13: 0 | X13: 0 | Y13: Matches
A14: 8 | B14: Mayowa Animasahun | C14: IRL | D14: DF | E14: Dundalk FC | F14: 20 | G14: 2003 | H14: 19 | I14: 16 | J14: 1275 | K14: 14.2 | L14: 0 | M14: 0 | N14: 0 | O14: 0 | P14: 0 | Q14: 0 | R14: 5 | S14: 0 | T14: 0 | U14: 0 | V14: 0 | W14: 0 | X14: 0 | Y14: Matches
A15: 9 | B15: Louie Annesley | C15: GIB | D15: DF | E15: Dundalk FC | F15: 23 | G15: 2000 | H15: 5 | I15: 3 | J15: 353 | K15: 3.9 | L15: 0 | M15: 0 | N15: 0 | O15: 0 | P15: 0 | Q15: 0 | R15: 2 | S15: 0 | T15: 0 | U15: 0 | V15: 0 | W15: 0 | X15: 0 | Y15: Matches
A16: 10 | B16: Shane Anthony Griffin | C16: IRL | D16: DF | E16: Shelbourne FC | F16: 29 | G16: 1994 | H16: 12 | I16: 8 | J16: 595 | K16: 6.6 | L16: 0 | M16: 0 | N16: 0 | O16: 0 | P16: 0 | Q16: 0 | R16: 4 | S16: 0 | T16: 0 | U16: 0 | V16: 0 | W16: 0 | X16: 0 | Y16: Matches
A17: 11 | B17: Wassim Aouachria | C17: ALG | D17: FW | E17: Galway United | F17: 23 | G17: 2000 | H17: 9 | I17: 1 | J17: 147 | K17: 1.6 | L17: 0 | M17: 0 | N17: 0 | O17: 0 | P17: 0 | Q17: 0 | R17: 0 | S17: 0 | T17: 0 | U17: 0 | V17: 0 | W17: 0 | X17: 0 | Y17: Matches
A18: 12 | B18: Gbemi Arubi | C18: IRL | D18: FW | E18: Waterford United | F18: 19 | G18: 2004 | H18: 13 | I18: 0 | J18: 152 | K18: 1.7 | L18: 0 | M18: 0 | N18: 0 | O18: 0 | P18: 0 | Q18: 0 | R18: 0 | S18: 0 | T18: 0 | U18: 0 | V18: 0 | W18: 0 | X18: 0 | Y18: Matches
... A49: 43 | B49: Jack Byrne | C49: IRL | D49: MF,FW | E49: Shamrock Rovers | F49: 27 | G49: 1996 | H49: 20 | I49: 14 | J49: 1231 | K49: 13.7 | L49: 1 | M49: 4 | N49: 5 | O49: 1 | P49: 0 | Q49: 0 | R49: 2 | S49: 0 | T49: 0.07 | U49: 0.29 | V49: 0.37 | W49: 0.07 | X49: 0.37 | Y49: Matches
A50: 44 | B50: James Byrne | C50: #VALUE! | D50: MF | E50: Drogheda United | H50: 1 | I50: 0 | J50: 20 | K50: 0.2 | L50: 0 | M50: 0 | N50: 0 | O50: 0 | P50: 0 | Q50: 0 | R50: 0 | S50: 0 | T50: 0 | U50: 0 | V50: 0 | W50: 0 | X50: 0 | Y50: Matches
A51: 45 | B51: Evan Caffrey | C51: IRL | D51: MF | E51: Shelbourne FC | F51: 20 | G51: 2003 | H51: 34 | I51: 17 | J51: 1822 | K51: 20.2 | L51: 3 | M51: 2 | N51: 5 | O51: 3 | P51: 0 | Q51: 0 | R51: 4 | S51: 0 | T51: 0.15 | U51: 0.1 | V51: 0.25 | W51: 0.15 | X51: 0.25 | Y51: Matches
A52: 46 | B52: Killian Cailloce | C52: IRL | D52: FW | E52: Drogheda United | F52: 18 | G52: 2005 | H52: 15 | I52: 0 | J52: 231 | K52: 2.6 | L52: 0 | M52: 0 | N52: 0 | O52: 0 | P52: 0 | Q52: 0 | R52: 1 | S52: 0 | T52: 0 | U52: 0 | V52: 0 | W52: 0 | X52: 0 | Y52: Matches
A53: 47 | B53: Hayden Cann | C53: ENG | D53: DF | E53: Drogheda United | F53: 20 | G53: 2003 | H53: 17 | I53: 17 | J53: 1530 | K53: 17 | L53: 1 | M53: 0 | N53: 1 | O53: 1 | P53: 0 | Q53: 0 | R53: 2 | S53: 0 | T53: 0.06 | U53: 0 | V53: 0.06 | W53: 0.06 | X53: 0.06 | Y53: Matches
A54: 48 | B54: Hayden Cann | C54: ENG | D54: DF | E54: Dundalk FC | F54: 20 | G54: 2003 | H54: 9 | I54: 9 | J54: 794 | K54: 8.8 | L54: 0 | M54: 1 | N54: 1 | O54: 0 | P54: 0 | Q54: 0 | R54: 1 | S54: 1 | T54: 0 | U54: 0.11 | V54: 0.11 | W54: 0 | X54: 0.11 | Y54: Matches
A55: 49 | B55: Jake Carroll | C55: IRL | D55: DF | E55: Bohemian FC | F55: 32 | G55: 1991 | H55: 9 | I55: 7 | J55: 636 | K55: 7.1 | L55: 0 | M55: 0 | N55: 0 | O55: 0 | P55: 0 | Q55: 0 | R55: 1 | S55: 0 | T55: 0 | U55: 0 | V55: 0 | W55: 0 | X55: 0 | Y55: Matches
A56: 50 | B56: Ellis Chapman | C56: ENG | D56: MF | E56: Sligo Rovers | F56: 23 | G56: 2001 | H56: 34 | I56: 33 | J56: 2764 | K56: 30.7 | L56: 9 | M56: 4 | N56: 13 | O56: 7 | P56: 2 | Q56: 2 | R56: 7 | S56: 0 | T56: 0.29 | U56: 0.13 | V56: 0.42 | W56: 0.23 | X56: 0.36 | Y56: Matches
A57: 51 | B57: Kacper Chorążka | C57: POL | D57: GK | E57: Bohemian FC | F57: 24 | G57: 1999 | H57: 34 | I57: 34 | J57: 3060 | K57: 34 | L57: 0 | M57: 0 | N57: 0 | O57: 0 | P57: 0 | Q57: 0 | R57: 1 | S57: 0 | T57: 0 | U57: 0 | V57: 0 | W57: 0 | X57: 0 | Y57: Matches
A58: 52 | B58: Brendan Clarke | C58: IRL | D58: GK | E58: Galway United | F58: 38 | G58: 1985 | H58: 36 | I58: 36 | J58: 3240 | K58: 36 | L58: 0 | M58: 0 | N58: 0 | O58: 0 | P58: 0 | Q58: 0 | R58: 2 | S58: 0 | T58: 0 | U58: 0 | V58: 0 | W58: 0 | X58: 0 | Y58: Matches
A59: 53 | B59: James Clarke | C59: IRL | D59: MF,FW | E59: Bohemian FC | F59: 23 | G59: 2001 | H59: 34 | I59: 26 | J59: 2295 | K59: 25.5 | L59: 4 | M59: 1 | N59: 5 | O59: 4 | P59: 0 | Q59: 0 | R59: 7 | S59: 0 | T59: 0.16 | U59: 0.04 | V59: 0.2 | W59: 0.16 | X59: 0.2 | Y59: Matches
A60: 54 | B60: Trevor Clarke | C60: IRL | D60: MF | E60: Shamrock Rovers | F60: 25 | G60: 1998 | H60: 21 | I60: 11 | J60: 917 | K60: 10.2 | L60: 0 | M60: 1 | N60: 1 | O60: 0 | P60: 0 | Q60: 0 | R60: 5 | S60: 0 | T60: 0 | U60: 0.1 | V60: 0.1 | W60: 0 | X60: 0.1 | Y60: Matches
A61: 55 | B61: Daniel Cleary | C61: IRL | D61: DF | E61: Shamrock Rovers | F61: 27 | G61: 1996 | H61: 31 | I61: 29 | J61: 2514 | K61: 27.9 | L61: 1 | M61: 1 | N61: 2 | O61: 1 | P61: 0 | Q61: 0 | R61: 10 | S61: 0 | T61: 0.04 | U61: 0.04 | V61: 0.07 | W61: 0.04 | X61: 0.07 | Y61: Matches
A62: 56 | B62: Ciarán Coll | C62: IRL | D62: DF | E62: Derry City | F62: 32 | G62: 1991 | H62: 24 | I62: 18 | J62: 1622 | K62: 18 | L62: 1 | M62: 1 | N62: 2 | O62: 1 | P62: 0 | Q62: 0 | R62: 4 | S62: 0 | T62: 0.06 | U62: 0.06 | V62: 0.11 | W62: 0.06 | X62: 0.11 | Y62: Matches
... A136: 130 | B136: Duncan Idehen | C136: ENG | D136: DF | E136: Derry City | F136: 21 | G136: 2002 | H136: 3 | I136: 2 | J136: 175 | K136: 1.9 | L136: 0 | M136: 0 | N136: 0 | O136: 0 | P136: 0 | Q136: 0 | R136: 2 | S136: 0 | T136: 0 | U136: 0 | V136: 0 | W136: 0 | X136: 0 | Y136: Matches
A137: 131 | B137: Mark Isong | D137: FW | E137: Shelbourne FC | H137: 1 | I137: 0 | J137: 4 | K137: 0 | L137: 0 | M137: 0 | N137: 0 | O137: 0 | P137: 0 | Q137: 0 | R137: 0 | S137: 0 | T137: 0 | U137: 0 | V137: 0 | W137: 0 | X137: 0 | Y137: Matches
A138: 132 | B138: Douglas James-Taylor | C138: ENG | D138: FW | E138: Drogheda United | F138: 22 | G138: 2001 | H138: 14 | I138: 14 | J138: 1160 | K138: 12.9 | L138: 6 | M138: 2 | N138: 8 | O138: 3 | P138: 3 | Q138: 3 | R138: 4 | S138: 0 | T138: 0.47 | U138: 0.16 | V138: 0.62 | W138: 0.23 | X138: 0.39 | Y138: Matches
A139: 133 | B139: William Jarvis | C139: ENG | D139: MF,FW | E139: Shelbourne FC | F139: 21 | G139: 2002 | H139: 25 | I139: 23 | J139: 1935 | K139: 21.5 | L139: 8 | M139: 4 | N139: 12 | O139: 4 | P139: 4 | Q139: 4 | R139: 0 | S139: 0 | T139: 0.37 | U139: 0.19 | V139: 0.56 | W139: 0.19 | X139: 0.37 | Y139: Matches
A140: 134 | B140: Zac Johnson | C140: ENG | D140: DF | E140: Dundalk FC | F140: 19 | G140: 2004 | H140: 18 | I140: 17 | J140: 1518 | K140: 16.9 | L140: 0 | M140: 0 | N140: 0 | O140: 0 | P140: 0 | Q140: 0 | R140: 3 | S140: 0 | T140: 0 | U140: 0 | V140: 0 | W140: 0 | X140: 0 | Y140: Matches
A141: 135 | B141: Louis Jones | C141: ENG | D141: GK | E141: Waterford United | F141: 25 | G141: 1998 | H141: 6 | I141: 6 | J141: 540 | K141: 6 | L141: 0 | M141: 0 | N141: 0 | O141: 0 | P141: 0 | Q141: 0 | R141: 0 | S141: 0 | T141: 0 | U141: 0 | V141: 0 | W141: 0 | X141: 0 | Y141: Matches
A142: 136 | B142: Conor Kane | C142: IRL | D142: DF,MF | E142: Drogheda United | F142: 25 | G142: 1998 | H142: 26 | I142: 21 | J142: 1906 | K142: 21.2 | L142: 1 | M142: 3 | N142: 4 | O142: 1 | P142: 0 | Q142: 0 | R142: 0 | S142: 0 | T142: 0.05 | U142: 0.14 | V142: 0.19 | W142: 0.05 | X142: 0.19 | Y142: Matches
A143: 137 | B143: Brandon Kavanagh | C143: IRL | D143: MF,FW | E143: St Patrick's | F143: 23 | G143: 2000 | H143: 34 | I143: 27 | J143: 2279 | K143: 25.3 | L143: 6 | M143: 13 | N143: 19 | O143: 5 | P143: 1 | Q143: 1 | R143: 2 | S143: 0 | T143: 0.24 | U143: 0.51 | V143: 0.75 | W143: 0.2 | X143: 0.71 | Y143: Matches
A144: 138 | B144: Cian Kavanagh | C144: IRL | D144: FW | E144: St Patrick's | F144: 21 | G144: 2003 | H144: 18 | I144: 2 | J144: 403 | K144: 4.5 | L144: 1 | M144: 1 | N144: 2 | O144: 1 | P144: 0 | Q144: 0 | R144: 1 | S144: 0 | T144: 0.22 | U144: 0.22 | V144: 0.45 | W144: 0.22 | X144: 0.45 | Y144: Matches
A145: 139 | B145: Leigh Kavanagh | C145: IRL | D145: DF,MF | E145: Bohemian FC | F145: 20 | G145: 2003 | H145: 7 | I145: 6 | J145: 528 | K145: 5.9 | L145: 0 | M145: 0 | N145: 0 | O145: 0 | P145: 0 | Q145: 0 | R145: 4 | S145: 1 | T145: 0 | U145: 0 | V145: 0 | W145: 0 | X145: 0 | Y145: Matches
A146: 140 | B146: Sean Kavanagh | C146: IRL | D146: MF,DF | E146: Shamrock Rovers | F146: 30 | G146: 1994 | H146: 12 | I146: 9 | J146: 602 | K146: 6.7 | L146: 0 | M146: 0 | N146: 0 | O146: 0 | P146: 0 | Q146: 0 | R146: 1 | S146: 0 | T146: 0 | U146: 0 | V146: 0 | W146: 0 | X146: 0 | Y146: Matches
...

Sheet Player pricing 
A1: Bohemian FC | F1: Waterford United | K1: Derry City
A2: James Talbot Goalkeeper | B2: 24/04/1997 (25) | C2: 1,80m | D2: €100k | F2: Matthew Connor Goalkeeper | G2: 08/04/1997 (25) | H2: 1,94m | I2: €20k | K2: Brian Maher Goalkeeper | L2: 01/11/2000 (22) | M2: 1,85m | N2: €150k
A3: Kacper Chorazka Goalkeeper | B3: 18/03/1999 (23) | C3: 1,89m | D3: €117k | F3: Louis Jones Goalkeeper | G3: 12/10/1998 (24) | H3: 1,85m | I3: €20k | K3: Tadhg Ryan Goalkeeper | L3: 09/04/1997 (25) | M3: 1,85m | N3: €75k
A4: Joe Collins Goalkeeper | B4: 25/02/2007 (15) | C4: - | D4: €117k | F4: Jason Healy Goalkeeper | G4: 06/03/2006 (16) | H4: - | I4: €20k | K4: Jack Mills Goalkeeper | L4: 21/10/2000 (22) | M4: 1,86m | N4: €117k
